<?xml version="1.0"?>
<robot name="mecanum_robot">

  <!-- Link raiz: referência no chão -->
  <link name="base_footprint">
    <visual>
      <origin xyz="0 0 0" rpy="0 0 0"/>
      <geometry>
        <box size="0.00025 0.00025 0.00025"/>
      </geometry>
    </visual>
  </link>

  <!-- Junta fixa entre base_footprint e base_link -->
  <joint name="base_link_joint" type="fixed">
    <origin xyz="0 0 0.0125" rpy="0 0 0"/>
    <parent link="base_footprint"/>
    <child link="base_link"/>
  </joint>

  <!-- Base sólida do robô -->
  <link name="base_link">
    <inertial>
      <origin xyz="0 0 0.0125"/>
      <mass value="50.0"/>
      <inertia ixx="10.0" ixy="0" ixz="0" iyy="10.0" iyz="0" izz="10.0"/>
    </inertial>
    <visual>
      <origin xyz="0 0 0.0125"/>
      <geometry>
        <box size="0.15 0.15 0.025"/>
      </geometry>
      <material name="grey">
        <color rgba="0.6 0.6 0.6 1"/>
      </material>
    </visual>
    <collision>
      <origin xyz="0 0 0.0125"/>
      <geometry>
        <box size="0.15 0.15 0.025"/>
      </geometry>
    </collision>
  </link>
  
  <!-- Definição das rodas com rotação ajustada (90° adicionais) -->
  <!-- Roda dianteira esquerda -->
  <link name="wheel_front_left">
    <inertial>
      <origin xyz="0 0 0"/>
      <mass value="2.0"/>
      <inertia ixx="0.01" ixy="0" ixz="0" iyy="0.01" iyz="0" izz="0.01"/>
    </inertial>
    <visual>
      <!-- Rotaciona: primeiro 90° em torno de Y e depois 90° em torno de Z -->
      <origin xyz="0 0 0" rpy="0 1.57 1.57"/>
      <geometry>
        <cylinder length="0.0125" radius="0.025"/>
      </geometry>
      <material name="black">
        <color rgba="0 0 0 1"/>
      </material>
    </visual>
    <collision>
      <origin xyz="0 0 0" rpy="0 1.57 1.57"/>
      <geometry>
        <cylinder length="0.0125" radius="0.025"/>
      </geometry>
    </collision>
  </link>

  <!-- Roda dianteira direita -->
  <link name="wheel_front_right">
    <inertial>
      <origin xyz="0 0 0"/>
      <mass value="2.0"/>
      <inertia ixx="0.01" ixy="0" ixz="0" iyy="0.01" iyz="0" izz="0.01"/>
    </inertial>
    <visual>
      <origin xyz="0 0 0" rpy="0 1.57 1.57"/>
      <geometry>
        <cylinder length="0.0125" radius="0.025"/>
      </geometry>
      <material name="black">
        <color rgba="0 0 0 1"/>
      </material>
    </visual>
    <collision>
      <origin xyz="0 0 0" rpy="0 1.57 1.57"/>
      <geometry>
        <cylinder length="0.0125" radius="0.025"/>
      </geometry>
    </collision>
  </link>

  <!-- Roda traseira esquerda -->
  <link name="wheel_rear_left">
    <inertial>
      <origin xyz="0 0 0"/>
      <mass value="2.0"/>
      <inertia ixx="0.01" ixy="0" ixz="0" iyy="0.01" iyz="0" izz="0.01"/>
    </inertial>
    <visual>
      <origin xyz="0 0 0" rpy="0 1.57 1.57"/>
      <geometry>
        <cylinder length="0.0125" radius="0.025"/>
      </geometry>
      <material name="black">
        <color rgba="0 0 0 1"/>
      </material>
    </visual>
    <collision>
      <origin xyz="0 0 0" rpy="0 1.57 1.57"/>
      <geometry>
        <cylinder length="0.0125" radius="0.025"/>
      </geometry>
    </collision>
  </link>

  <!-- Roda traseira direita -->
  <link name="wheel_rear_right">
    <inertial>
      <origin xyz="0 0 0"/>
      <mass value="2.0"/>
      <inertia ixx="0.01" ixy="0" ixz="0" iyy="0.01" iyz="0" izz="0.01"/>
    </inertial>
    <visual>
      <origin xyz="0 0 0" rpy="0 1.57 1.57"/>
      <geometry>
        <cylinder length="0.0125" radius="0.025"/>
      </geometry>
      <material name="black">
        <color rgba="0 0 0 1"/>
      </material>
    </visual>
    <collision>
      <origin xyz="0 0 0" rpy="0 1.57 1.57"/>
      <geometry>
        <cylinder length="0.0125" radius="0.025"/>
      </geometry>
    </collision>
  </link>

  <!-- Juntas das rodas com eixo de rotação ajustado -->
  <joint name="joint_wheel_front_left" type="revolute">
    <origin xyz="0.075 0.075 0.0125" rpy="0 0 0"/>
    <parent link="base_link"/>
    <child link="wheel_front_left"/>
    <axis xyz="0 1 0"/>
    <limit effort="100" velocity="10"/>
  </joint>

  <joint name="joint_wheel_front_right" type="revolute">
    <origin xyz="0.075 -0.075 0.0125" rpy="0 0 0"/>
    <parent link="base_link"/>
    <child link="wheel_front_right"/>
    <axis xyz="0 1 0"/>
    <limit effort="100" velocity="10"/>
  </joint>

  <joint name="joint_wheel_rear_left" type="revolute">
    <origin xyz="-0.075 0.075 0.0125" rpy="0 0 0"/>
    <parent link="base_link"/>
    <child link="wheel_rear_left"/>
    <axis xyz="0 1 0"/>
    <limit effort="100" velocity="10"/>
  </joint>

  <joint name="joint_wheel_rear_right" type="revolute">
    <origin xyz="-0.075 -0.075 0.0125" rpy="0 0 0"/>
    <parent link="base_link"/>
    <child link="wheel_rear_right"/>
    <axis xyz="0 1 0"/>
    <limit effort="100" velocity="10"/>
  </joint>

  <!-- LIDAR colado na base -->
  <link name="lidar">
    <material>Gazebo/FlatBlack</material>
    <inertial>
      <origin xyz="0 0 0"/>
      <mass value="1.0"/>
      <inertia ixx="0.001" ixy="0" ixz="0" iyy="0.001" iyz="0" izz="0.001"/>
    </inertial>
    <visual>
      <origin xyz="0 0 0" rpy="0 0 0"/>
      <geometry>
        <cylinder radius="0.0125" length="0.0125"/>
      </geometry>
      <material name="red">
        <color rgba="1 0 0 1"/>
      </material>
    </visual>
    <collision>
      <origin xyz="0 0 0" rpy="0 0 0"/>
      <geometry>
        <cylinder radius="0.0125" length="0.0125"/>
      </geometry>
    </collision>
  </link>

  <joint name="lidar_joint" type="fixed">
    <origin xyz="0 0 0.03875" rpy="0 0 0"/>
    <parent link="base_link"/>
    <child link="lidar"/>
  </joint>

  <!-- Plugin do Gazebo para controle planar -->
  <gazebo>
    <plugin name="object_controller" filename="libgazebo_ros_planar_move.so">
      <commandTopic>cmd_vel</commandTopic>
      <odometryTopic>odom</odometryTopic>
      <odometryFrame>odom</odometryFrame>
      <odometryRate>20.0</odometryRate>
      <robotBaseFrame>base_footprint</robotBaseFrame>
    </plugin>
  </gazebo>

  <!-- Configuração do sensor LIDAR para o Gazebo -->
  <gazebo reference="lidar">
    <material>Gazebo/FlatBlack</material>
    <sensor type="ray" name="lds_lfcd_sensor">
      <pose>0 0 0 0 0 0</pose>
      <!-- Altere para 'true' ou 'false' conforme desejar visualizar o sensor -->
      <visualize>true</visualize>
      <update_rate>5</update_rate>
      <ray>
        <scan>
          <horizontal>
            <samples>360</samples>
            <resolution>1</resolution>
            <min_angle>0.0</min_angle>
            <max_angle>6.28319</max_angle>
          </horizontal>
        </scan>
        <range>
          <min>0.120</min>
          <max>3.5</max>
          <resolution>0.015</resolution>
        </range>
        <noise>
          <type>gaussian</type>
          <mean>0.0</mean>
          <stddev>0.01</stddev>
        </noise>
      </ray>
      <plugin name="gazebo_ros_lds_lfcd_controller" filename="libgazebo_ros_laser.so">
        <topicName>scan</topicName>
        <!-- Use o nome do frame associado ao seu sensor, podendo ser 'lidar' -->
        <frameName>lidar</frameName>
      </plugin>
    </sensor>
  </gazebo>

</robot>
